2020-02-11 10:27:01,584 INFO: bugTracker startup [in C:\Users\josep\OneDrive\Documents\Programming\Portfolio\bugTracker\app\__init__.py:43]
2020-02-11 10:27:23,899 ERROR: Exception on /edit_profile [POST] [in c:\users\josep\onedrive\documents\programming\portfolio\bugtracker\env\lib\site-packages\flask\app.py:1890]
Traceback (most recent call last):
  File "c:\users\josep\onedrive\documents\programming\portfolio\bugtracker\env\lib\site-packages\sqlalchemy\engine\base.py", line 1245, in _execute_context
    self.dialect.do_execute(
  File "c:\users\josep\onedrive\documents\programming\portfolio\bugtracker\env\lib\site-packages\sqlalchemy\engine\default.py", line 588, in do_execute
    cursor.execute(statement, parameters)
psycopg2.errors.UniqueViolation: duplicate key value violates unique constraint "ix_users_username"
DETAIL:  Key (username)=(Susan) already exists.


The above exception was the direct cause of the following exception:

Traceback (most recent call last):
  File "c:\users\josep\onedrive\documents\programming\portfolio\bugtracker\env\lib\site-packages\flask\app.py", line 2446, in wsgi_app
    response = self.full_dispatch_request()
  File "c:\users\josep\onedrive\documents\programming\portfolio\bugtracker\env\lib\site-packages\flask\app.py", line 1951, in full_dispatch_request
    rv = self.handle_user_exception(e)
  File "c:\users\josep\onedrive\documents\programming\portfolio\bugtracker\env\lib\site-packages\flask\app.py", line 1820, in handle_user_exception
    reraise(exc_type, exc_value, tb)
  File "c:\users\josep\onedrive\documents\programming\portfolio\bugtracker\env\lib\site-packages\flask\_compat.py", line 39, in reraise
    raise value
  File "c:\users\josep\onedrive\documents\programming\portfolio\bugtracker\env\lib\site-packages\flask\app.py", line 1949, in full_dispatch_request
    rv = self.dispatch_request()
  File "c:\users\josep\onedrive\documents\programming\portfolio\bugtracker\env\lib\site-packages\flask\app.py", line 1935, in dispatch_request
    return self.view_functions[rule.endpoint](**req.view_args)
  File "c:\users\josep\onedrive\documents\programming\portfolio\bugtracker\env\lib\site-packages\flask_login\utils.py", line 272, in decorated_view
    return func(*args, **kwargs)
  File "C:\Users\josep\OneDrive\Documents\Programming\Portfolio\bugTracker\app\routes.py", line 98, in edit_profile
    db.session.commit()
  File "c:\users\josep\onedrive\documents\programming\portfolio\bugtracker\env\lib\site-packages\sqlalchemy\orm\scoping.py", line 162, in do
    return getattr(self.registry(), name)(*args, **kwargs)
  File "c:\users\josep\onedrive\documents\programming\portfolio\bugtracker\env\lib\site-packages\sqlalchemy\orm\session.py", line 1036, in commit
    self.transaction.commit()
  File "c:\users\josep\onedrive\documents\programming\portfolio\bugtracker\env\lib\site-packages\sqlalchemy\orm\session.py", line 503, in commit
    self._prepare_impl()
  File "c:\users\josep\onedrive\documents\programming\portfolio\bugtracker\env\lib\site-packages\sqlalchemy\orm\session.py", line 482, in _prepare_impl
    self.session.flush()
  File "c:\users\josep\onedrive\documents\programming\portfolio\bugtracker\env\lib\site-packages\sqlalchemy\orm\session.py", line 2479, in flush
    self._flush(objects)
  File "c:\users\josep\onedrive\documents\programming\portfolio\bugtracker\env\lib\site-packages\sqlalchemy\orm\session.py", line 2617, in _flush
    transaction.rollback(_capture_exception=True)
  File "c:\users\josep\onedrive\documents\programming\portfolio\bugtracker\env\lib\site-packages\sqlalchemy\util\langhelpers.py", line 68, in __exit__
    compat.reraise(exc_type, exc_value, exc_tb)
  File "c:\users\josep\onedrive\documents\programming\portfolio\bugtracker\env\lib\site-packages\sqlalchemy\util\compat.py", line 153, in reraise
    raise value
  File "c:\users\josep\onedrive\documents\programming\portfolio\bugtracker\env\lib\site-packages\sqlalchemy\orm\session.py", line 2577, in _flush
    flush_context.execute()
  File "c:\users\josep\onedrive\documents\programming\portfolio\bugtracker\env\lib\site-packages\sqlalchemy\orm\unitofwork.py", line 422, in execute
    rec.execute(self)
  File "c:\users\josep\onedrive\documents\programming\portfolio\bugtracker\env\lib\site-packages\sqlalchemy\orm\unitofwork.py", line 586, in execute
    persistence.save_obj(
  File "c:\users\josep\onedrive\documents\programming\portfolio\bugtracker\env\lib\site-packages\sqlalchemy\orm\persistence.py", line 230, in save_obj
    _emit_update_statements(
  File "c:\users\josep\onedrive\documents\programming\portfolio\bugtracker\env\lib\site-packages\sqlalchemy\orm\persistence.py", line 995, in _emit_update_statements
    c = cached_connections[connection].execute(
  File "c:\users\josep\onedrive\documents\programming\portfolio\bugtracker\env\lib\site-packages\sqlalchemy\engine\base.py", line 982, in execute
    return meth(self, multiparams, params)
  File "c:\users\josep\onedrive\documents\programming\portfolio\bugtracker\env\lib\site-packages\sqlalchemy\sql\elements.py", line 293, in _execute_on_connection
    return connection._execute_clauseelement(self, multiparams, params)
  File "c:\users\josep\onedrive\documents\programming\portfolio\bugtracker\env\lib\site-packages\sqlalchemy\engine\base.py", line 1095, in _execute_clauseelement
    ret = self._execute_context(
  File "c:\users\josep\onedrive\documents\programming\portfolio\bugtracker\env\lib\site-packages\sqlalchemy\engine\base.py", line 1249, in _execute_context
    self._handle_dbapi_exception(
  File "c:\users\josep\onedrive\documents\programming\portfolio\bugtracker\env\lib\site-packages\sqlalchemy\engine\base.py", line 1476, in _handle_dbapi_exception
    util.raise_from_cause(sqlalchemy_exception, exc_info)
  File "c:\users\josep\onedrive\documents\programming\portfolio\bugtracker\env\lib\site-packages\sqlalchemy\util\compat.py", line 398, in raise_from_cause
    reraise(type(exception), exception, tb=exc_tb, cause=cause)
  File "c:\users\josep\onedrive\documents\programming\portfolio\bugtracker\env\lib\site-packages\sqlalchemy\util\compat.py", line 152, in reraise
    raise value.with_traceback(tb)
  File "c:\users\josep\onedrive\documents\programming\portfolio\bugtracker\env\lib\site-packages\sqlalchemy\engine\base.py", line 1245, in _execute_context
    self.dialect.do_execute(
  File "c:\users\josep\onedrive\documents\programming\portfolio\bugtracker\env\lib\site-packages\sqlalchemy\engine\default.py", line 588, in do_execute
    cursor.execute(statement, parameters)
sqlalchemy.exc.IntegrityError: (psycopg2.errors.UniqueViolation) duplicate key value violates unique constraint "ix_users_username"
DETAIL:  Key (username)=(Susan) already exists.

[SQL: UPDATE users SET username=%(username)s WHERE users.id = %(users_id)s]
[parameters: {'username': 'Susan', 'users_id': 6}]
(Background on this error at: http://sqlalche.me/e/gkpj)
2020-02-11 10:29:23,913 INFO: bugTracker startup [in C:\Users\josep\OneDrive\Documents\Programming\Portfolio\bugTracker\app\__init__.py:43]
2020-02-11 10:42:40,426 INFO: bugTracker startup [in C:\Users\josep\OneDrive\Documents\Programming\Portfolio\bugTracker\app\__init__.py:43]
2020-02-11 10:43:27,620 INFO: bugTracker startup [in C:\Users\josep\OneDrive\Documents\Programming\Portfolio\bugTracker\app\__init__.py:43]
2020-02-11 10:44:44,824 INFO: bugTracker startup [in C:\Users\josep\OneDrive\Documents\Programming\Portfolio\bugTracker\app\__init__.py:43]
2020-02-11 10:45:10,924 INFO: bugTracker startup [in C:\Users\josep\OneDrive\Documents\Programming\Portfolio\bugTracker\app\__init__.py:43]
2020-02-11 10:45:22,285 INFO: bugTracker startup [in C:\Users\josep\OneDrive\Documents\Programming\Portfolio\bugTracker\app\__init__.py:43]
2020-02-11 10:50:59,334 INFO: bugTracker startup [in C:\Users\josep\OneDrive\Documents\Programming\Portfolio\bugTracker\app\__init__.py:43]
2020-02-11 10:51:06,679 INFO: bugTracker startup [in C:\Users\josep\OneDrive\Documents\Programming\Portfolio\bugTracker\app\__init__.py:43]
2020-02-11 10:51:46,233 INFO: bugTracker startup [in C:\Users\josep\OneDrive\Documents\Programming\Portfolio\bugTracker\app\__init__.py:43]
2020-02-11 10:51:54,938 ERROR: Exception on /create [GET] [in c:\users\josep\onedrive\documents\programming\portfolio\bugtracker\env\lib\site-packages\flask\app.py:1890]
Traceback (most recent call last):
  File "c:\users\josep\onedrive\documents\programming\portfolio\bugtracker\env\lib\site-packages\flask\app.py", line 2446, in wsgi_app
    response = self.full_dispatch_request()
  File "c:\users\josep\onedrive\documents\programming\portfolio\bugtracker\env\lib\site-packages\flask\app.py", line 1951, in full_dispatch_request
    rv = self.handle_user_exception(e)
  File "c:\users\josep\onedrive\documents\programming\portfolio\bugtracker\env\lib\site-packages\flask\app.py", line 1820, in handle_user_exception
    reraise(exc_type, exc_value, tb)
  File "c:\users\josep\onedrive\documents\programming\portfolio\bugtracker\env\lib\site-packages\flask\_compat.py", line 39, in reraise
    raise value
  File "c:\users\josep\onedrive\documents\programming\portfolio\bugtracker\env\lib\site-packages\flask\app.py", line 1949, in full_dispatch_request
    rv = self.dispatch_request()
  File "c:\users\josep\onedrive\documents\programming\portfolio\bugtracker\env\lib\site-packages\flask\app.py", line 1935, in dispatch_request
    return self.view_functions[rule.endpoint](**req.view_args)
  File "c:\users\josep\onedrive\documents\programming\portfolio\bugtracker\env\lib\site-packages\flask_login\utils.py", line 272, in decorated_view
    return func(*args, **kwargs)
  File "C:\Users\josep\OneDrive\Documents\Programming\Portfolio\bugTracker\app\routes.py", line 91, in create
    if ticket.validate_on_submit():
UnboundLocalError: local variable 'ticket' referenced before assignment
2020-02-11 10:52:20,228 INFO: bugTracker startup [in C:\Users\josep\OneDrive\Documents\Programming\Portfolio\bugTracker\app\__init__.py:43]
