2020-02-11 10:52:22,431 ERROR: Exception on /create [GET] [in c:\users\josep\onedrive\documents\programming\portfolio\bugtracker\env\lib\site-packages\flask\app.py:1890]
Traceback (most recent call last):
  File "c:\users\josep\onedrive\documents\programming\portfolio\bugtracker\env\lib\site-packages\flask\app.py", line 2446, in wsgi_app
    response = self.full_dispatch_request()
  File "c:\users\josep\onedrive\documents\programming\portfolio\bugtracker\env\lib\site-packages\flask\app.py", line 1951, in full_dispatch_request
    rv = self.handle_user_exception(e)
  File "c:\users\josep\onedrive\documents\programming\portfolio\bugtracker\env\lib\site-packages\flask\app.py", line 1820, in handle_user_exception
    reraise(exc_type, exc_value, tb)
  File "c:\users\josep\onedrive\documents\programming\portfolio\bugtracker\env\lib\site-packages\flask\_compat.py", line 39, in reraise
    raise value
  File "c:\users\josep\onedrive\documents\programming\portfolio\bugtracker\env\lib\site-packages\flask\app.py", line 1949, in full_dispatch_request
    rv = self.dispatch_request()
  File "c:\users\josep\onedrive\documents\programming\portfolio\bugtracker\env\lib\site-packages\flask\app.py", line 1935, in dispatch_request
    return self.view_functions[rule.endpoint](**req.view_args)
  File "c:\users\josep\onedrive\documents\programming\portfolio\bugtracker\env\lib\site-packages\flask_login\utils.py", line 272, in decorated_view
    return func(*args, **kwargs)
  File "C:\Users\josep\OneDrive\Documents\Programming\Portfolio\bugTracker\app\routes.py", line 91, in create
    if ticket.validate_on_submit():
UnboundLocalError: local variable 'ticket' referenced before assignment
2020-02-11 10:52:33,729 INFO: bugTracker startup [in C:\Users\josep\OneDrive\Documents\Programming\Portfolio\bugTracker\app\__init__.py:43]
2020-02-11 10:52:35,563 ERROR: Exception on /create [GET] [in c:\users\josep\onedrive\documents\programming\portfolio\bugtracker\env\lib\site-packages\flask\app.py:1890]
Traceback (most recent call last):
  File "c:\users\josep\onedrive\documents\programming\portfolio\bugtracker\env\lib\site-packages\flask\app.py", line 2446, in wsgi_app
    response = self.full_dispatch_request()
  File "c:\users\josep\onedrive\documents\programming\portfolio\bugtracker\env\lib\site-packages\flask\app.py", line 1951, in full_dispatch_request
    rv = self.handle_user_exception(e)
  File "c:\users\josep\onedrive\documents\programming\portfolio\bugtracker\env\lib\site-packages\flask\app.py", line 1820, in handle_user_exception
    reraise(exc_type, exc_value, tb)
  File "c:\users\josep\onedrive\documents\programming\portfolio\bugtracker\env\lib\site-packages\flask\_compat.py", line 39, in reraise
    raise value
  File "c:\users\josep\onedrive\documents\programming\portfolio\bugtracker\env\lib\site-packages\flask\app.py", line 1949, in full_dispatch_request
    rv = self.dispatch_request()
  File "c:\users\josep\onedrive\documents\programming\portfolio\bugtracker\env\lib\site-packages\flask\app.py", line 1935, in dispatch_request
    return self.view_functions[rule.endpoint](**req.view_args)
  File "c:\users\josep\onedrive\documents\programming\portfolio\bugtracker\env\lib\site-packages\flask_login\utils.py", line 272, in decorated_view
    return func(*args, **kwargs)
  File "C:\Users\josep\OneDrive\Documents\Programming\Portfolio\bugTracker\app\routes.py", line 91, in create
    if ticket.validate_on_submit():
UnboundLocalError: local variable 'ticket' referenced before assignment
2020-02-11 19:18:59,797 INFO: bugTracker startup [in C:\Users\josep\OneDrive\Documents\Programming\Portfolio\bugTracker\app\__init__.py:43]
2020-02-11 19:19:41,301 ERROR: Exception on /create [GET] [in c:\users\josep\onedrive\documents\programming\portfolio\bugtracker\env\lib\site-packages\flask\app.py:1890]
Traceback (most recent call last):
  File "c:\users\josep\onedrive\documents\programming\portfolio\bugtracker\env\lib\site-packages\flask\app.py", line 2446, in wsgi_app
    response = self.full_dispatch_request()
  File "c:\users\josep\onedrive\documents\programming\portfolio\bugtracker\env\lib\site-packages\flask\app.py", line 1951, in full_dispatch_request
    rv = self.handle_user_exception(e)
  File "c:\users\josep\onedrive\documents\programming\portfolio\bugtracker\env\lib\site-packages\flask\app.py", line 1820, in handle_user_exception
    reraise(exc_type, exc_value, tb)
  File "c:\users\josep\onedrive\documents\programming\portfolio\bugtracker\env\lib\site-packages\flask\_compat.py", line 39, in reraise
    raise value
  File "c:\users\josep\onedrive\documents\programming\portfolio\bugtracker\env\lib\site-packages\flask\app.py", line 1949, in full_dispatch_request
    rv = self.dispatch_request()
  File "c:\users\josep\onedrive\documents\programming\portfolio\bugtracker\env\lib\site-packages\flask\app.py", line 1935, in dispatch_request
    return self.view_functions[rule.endpoint](**req.view_args)
  File "c:\users\josep\onedrive\documents\programming\portfolio\bugtracker\env\lib\site-packages\flask_login\utils.py", line 272, in decorated_view
    return func(*args, **kwargs)
  File "C:\Users\josep\OneDrive\Documents\Programming\Portfolio\bugTracker\app\routes.py", line 91, in create
    if ticket.validate_on_submit():
UnboundLocalError: local variable 'ticket' referenced before assignment
2020-02-11 19:22:03,080 INFO: bugTracker startup [in C:\Users\josep\OneDrive\Documents\Programming\Portfolio\bugTracker\app\__init__.py:43]
2020-02-11 19:22:11,528 ERROR: Exception on /create [GET] [in c:\users\josep\onedrive\documents\programming\portfolio\bugtracker\env\lib\site-packages\flask\app.py:1890]
Traceback (most recent call last):
  File "c:\users\josep\onedrive\documents\programming\portfolio\bugtracker\env\lib\site-packages\flask\app.py", line 2446, in wsgi_app
    response = self.full_dispatch_request()
  File "c:\users\josep\onedrive\documents\programming\portfolio\bugtracker\env\lib\site-packages\flask\app.py", line 1951, in full_dispatch_request
    rv = self.handle_user_exception(e)
  File "c:\users\josep\onedrive\documents\programming\portfolio\bugtracker\env\lib\site-packages\flask\app.py", line 1820, in handle_user_exception
    reraise(exc_type, exc_value, tb)
  File "c:\users\josep\onedrive\documents\programming\portfolio\bugtracker\env\lib\site-packages\flask\_compat.py", line 39, in reraise
    raise value
  File "c:\users\josep\onedrive\documents\programming\portfolio\bugtracker\env\lib\site-packages\flask\app.py", line 1949, in full_dispatch_request
    rv = self.dispatch_request()
  File "c:\users\josep\onedrive\documents\programming\portfolio\bugtracker\env\lib\site-packages\flask\app.py", line 1935, in dispatch_request
    return self.view_functions[rule.endpoint](**req.view_args)
  File "c:\users\josep\onedrive\documents\programming\portfolio\bugtracker\env\lib\site-packages\flask_login\utils.py", line 272, in decorated_view
    return func(*args, **kwargs)
  File "C:\Users\josep\OneDrive\Documents\Programming\Portfolio\bugTracker\app\routes.py", line 97, in create
    return render_template('create.html', title=Createticket, form=form)
NameError: name 'Createticket' is not defined
2020-02-11 19:22:59,327 INFO: bugTracker startup [in C:\Users\josep\OneDrive\Documents\Programming\Portfolio\bugTracker\app\__init__.py:43]
