2020-02-11 19:23:02,091 ERROR: Exception on /create [GET] [in c:\users\josep\onedrive\documents\programming\portfolio\bugtracker\env\lib\site-packages\flask\app.py:1890]
Traceback (most recent call last):
  File "c:\users\josep\onedrive\documents\programming\portfolio\bugtracker\env\lib\site-packages\flask\app.py", line 2446, in wsgi_app
    response = self.full_dispatch_request()
  File "c:\users\josep\onedrive\documents\programming\portfolio\bugtracker\env\lib\site-packages\flask\app.py", line 1951, in full_dispatch_request
    rv = self.handle_user_exception(e)
  File "c:\users\josep\onedrive\documents\programming\portfolio\bugtracker\env\lib\site-packages\flask\app.py", line 1820, in handle_user_exception
    reraise(exc_type, exc_value, tb)
  File "c:\users\josep\onedrive\documents\programming\portfolio\bugtracker\env\lib\site-packages\flask\_compat.py", line 39, in reraise
    raise value
  File "c:\users\josep\onedrive\documents\programming\portfolio\bugtracker\env\lib\site-packages\flask\app.py", line 1949, in full_dispatch_request
    rv = self.dispatch_request()
  File "c:\users\josep\onedrive\documents\programming\portfolio\bugtracker\env\lib\site-packages\flask\app.py", line 1935, in dispatch_request
    return self.view_functions[rule.endpoint](**req.view_args)
  File "c:\users\josep\onedrive\documents\programming\portfolio\bugtracker\env\lib\site-packages\flask_login\utils.py", line 272, in decorated_view
    return func(*args, **kwargs)
  File "C:\Users\josep\OneDrive\Documents\Programming\Portfolio\bugTracker\app\routes.py", line 97, in create
    return render_template('create.html', title='Createticket', form=form)
  File "c:\users\josep\onedrive\documents\programming\portfolio\bugtracker\env\lib\site-packages\flask\templating.py", line 138, in render_template
    ctx.app.jinja_env.get_or_select_template(template_name_or_list),
  File "c:\users\josep\onedrive\documents\programming\portfolio\bugtracker\env\lib\site-packages\jinja2\environment.py", line 930, in get_or_select_template
    return self.get_template(template_name_or_list, parent, globals)
  File "c:\users\josep\onedrive\documents\programming\portfolio\bugtracker\env\lib\site-packages\jinja2\environment.py", line 883, in get_template
    return self._load_template(name, self.make_globals(globals))
  File "c:\users\josep\onedrive\documents\programming\portfolio\bugtracker\env\lib\site-packages\jinja2\environment.py", line 857, in _load_template
    template = self.loader.load(self, name, globals)
  File "c:\users\josep\onedrive\documents\programming\portfolio\bugtracker\env\lib\site-packages\jinja2\loaders.py", line 129, in load
    code = environment.compile(source, name, filename)
  File "c:\users\josep\onedrive\documents\programming\portfolio\bugtracker\env\lib\site-packages\jinja2\environment.py", line 638, in compile
    self.handle_exception(source=source_hint)
  File "c:\users\josep\onedrive\documents\programming\portfolio\bugtracker\env\lib\site-packages\jinja2\environment.py", line 832, in handle_exception
    reraise(*rewrite_traceback_stack(source=source))
  File "c:\users\josep\onedrive\documents\programming\portfolio\bugtracker\env\lib\site-packages\jinja2\_compat.py", line 28, in reraise
    raise value.with_traceback(tb)
  File "C:\Users\josep\OneDrive\Documents\Programming\Portfolio\bugTracker\app\templates\create.html", line 12, in template
    {% endfor %}
jinja2.exceptions.TemplateSyntaxError: Unexpected end of template. Jinja was looking for the following tags: 'endblock'. The innermost block that needs to be closed is 'block'.
2020-02-11 19:23:33,070 INFO: bugTracker startup [in C:\Users\josep\OneDrive\Documents\Programming\Portfolio\bugTracker\app\__init__.py:43]
2020-02-11 19:25:17,106 INFO: bugTracker startup [in C:\Users\josep\OneDrive\Documents\Programming\Portfolio\bugTracker\app\__init__.py:43]
2020-02-11 19:26:44,173 INFO: bugTracker startup [in C:\Users\josep\OneDrive\Documents\Programming\Portfolio\bugTracker\app\__init__.py:43]
2020-02-11 19:35:09,406 INFO: bugTracker startup [in C:\Users\josep\OneDrive\Documents\Programming\Portfolio\bugTracker\app\__init__.py:43]
2020-02-11 19:36:38,831 INFO: bugTracker startup [in C:\Users\josep\OneDrive\Documents\Programming\Portfolio\bugTracker\app\__init__.py:43]
2020-02-11 19:37:23,928 INFO: bugTracker startup [in C:\Users\josep\OneDrive\Documents\Programming\Portfolio\bugTracker\app\__init__.py:43]
2020-02-11 19:40:18,913 INFO: bugTracker startup [in C:\Users\josep\OneDrive\Documents\Programming\Portfolio\bugTracker\app\__init__.py:43]
2020-02-11 19:41:00,164 INFO: bugTracker startup [in C:\Users\josep\OneDrive\Documents\Programming\Portfolio\bugTracker\app\__init__.py:43]
2020-02-11 19:45:50,775 INFO: bugTracker startup [in C:\Users\josep\OneDrive\Documents\Programming\Portfolio\bugTracker\app\__init__.py:43]
2020-02-11 19:45:59,835 ERROR: Exception on /login [POST] [in c:\users\josep\onedrive\documents\programming\portfolio\bugtracker\env\lib\site-packages\flask\app.py:1890]
Traceback (most recent call last):
  File "c:\users\josep\onedrive\documents\programming\portfolio\bugtracker\env\lib\site-packages\flask\app.py", line 2446, in wsgi_app
    response = self.full_dispatch_request()
  File "c:\users\josep\onedrive\documents\programming\portfolio\bugtracker\env\lib\site-packages\flask\app.py", line 1951, in full_dispatch_request
    rv = self.handle_user_exception(e)
  File "c:\users\josep\onedrive\documents\programming\portfolio\bugtracker\env\lib\site-packages\flask\app.py", line 1820, in handle_user_exception
    reraise(exc_type, exc_value, tb)
  File "c:\users\josep\onedrive\documents\programming\portfolio\bugtracker\env\lib\site-packages\flask\_compat.py", line 39, in reraise
    raise value
  File "c:\users\josep\onedrive\documents\programming\portfolio\bugtracker\env\lib\site-packages\flask\app.py", line 1949, in full_dispatch_request
    rv = self.dispatch_request()
  File "c:\users\josep\onedrive\documents\programming\portfolio\bugtracker\env\lib\site-packages\flask\app.py", line 1935, in dispatch_request
    return self.view_functions[rule.endpoint](**req.view_args)
  File "C:\Users\josep\OneDrive\Documents\Programming\Portfolio\bugTracker\app\routes.py", line 31, in login
    if user is None or not user.check_password(form.password.data):
  File "C:\Users\josep\OneDrive\Documents\Programming\Portfolio\bugTracker\app\models.py", line 22, in check_password
    return check_password_hash(self.password_hash, password)
  File "c:\users\josep\onedrive\documents\programming\portfolio\bugtracker\env\lib\site-packages\werkzeug\security.py", line 218, in check_password_hash
    if pwhash.count("$") < 2:
AttributeError: 'NoneType' object has no attribute 'count'
2020-02-11 19:51:13,950 INFO: bugTracker startup [in C:\Users\josep\OneDrive\Documents\Programming\Portfolio\bugTracker\app\__init__.py:43]
2020-02-11 19:55:31,766 INFO: bugTracker startup [in C:\Users\josep\OneDrive\Documents\Programming\Portfolio\bugTracker\app\__init__.py:43]
2020-02-11 20:04:08,412 INFO: bugTracker startup [in C:\Users\josep\OneDrive\Documents\Programming\Portfolio\bugTracker\app\__init__.py:43]
2020-02-11 20:04:22,091 INFO: bugTracker startup [in C:\Users\josep\OneDrive\Documents\Programming\Portfolio\bugTracker\app\__init__.py:43]
2020-02-11 20:05:35,143 INFO: bugTracker startup [in C:\Users\josep\OneDrive\Documents\Programming\Portfolio\bugTracker\app\__init__.py:43]
2020-02-11 20:07:10,013 INFO: bugTracker startup [in C:\Users\josep\OneDrive\Documents\Programming\Portfolio\bugTracker\app\__init__.py:43]
2020-02-11 20:07:18,024 INFO: bugTracker startup [in C:\Users\josep\OneDrive\Documents\Programming\Portfolio\bugTracker\app\__init__.py:43]
2020-02-11 20:07:26,453 INFO: bugTracker startup [in C:\Users\josep\OneDrive\Documents\Programming\Portfolio\bugTracker\app\__init__.py:43]
