2020-02-12 08:01:32,951 ERROR: Exception on /login [POST] [in c:\users\josep\onedrive\documents\programming\portfolio\bugtracker\env\lib\site-packages\flask\app.py:1890]
Traceback (most recent call last):
  File "c:\users\josep\onedrive\documents\programming\portfolio\bugtracker\env\lib\site-packages\flask\app.py", line 2446, in wsgi_app
    response = self.full_dispatch_request()
  File "c:\users\josep\onedrive\documents\programming\portfolio\bugtracker\env\lib\site-packages\flask\app.py", line 1951, in full_dispatch_request
    rv = self.handle_user_exception(e)
  File "c:\users\josep\onedrive\documents\programming\portfolio\bugtracker\env\lib\site-packages\flask\app.py", line 1820, in handle_user_exception
    reraise(exc_type, exc_value, tb)
  File "c:\users\josep\onedrive\documents\programming\portfolio\bugtracker\env\lib\site-packages\flask\_compat.py", line 39, in reraise
    raise value
  File "c:\users\josep\onedrive\documents\programming\portfolio\bugtracker\env\lib\site-packages\flask\app.py", line 1949, in full_dispatch_request
    rv = self.dispatch_request()
  File "c:\users\josep\onedrive\documents\programming\portfolio\bugtracker\env\lib\site-packages\flask\app.py", line 1935, in dispatch_request
    return self.view_functions[rule.endpoint](**req.view_args)
  File "C:\Users\josep\OneDrive\Documents\Programming\Portfolio\bugTracker\app\routes.py", line 30, in login
    user = User.query.filter_by(username=form.username.data).first()
  File "c:\users\josep\onedrive\documents\programming\portfolio\bugtracker\env\lib\site-packages\flask_sqlalchemy\__init__.py", line 517, in __get__
    mapper = orm.class_mapper(type)
  File "c:\users\josep\onedrive\documents\programming\portfolio\bugtracker\env\lib\site-packages\sqlalchemy\orm\base.py", line 441, in class_mapper
    mapper = _inspect_mapped_class(class_, configure=configure)
  File "c:\users\josep\onedrive\documents\programming\portfolio\bugtracker\env\lib\site-packages\sqlalchemy\orm\base.py", line 420, in _inspect_mapped_class
    mapper._configure_all()
  File "c:\users\josep\onedrive\documents\programming\portfolio\bugtracker\env\lib\site-packages\sqlalchemy\orm\mapper.py", line 1337, in _configure_all
    configure_mappers()
  File "c:\users\josep\onedrive\documents\programming\portfolio\bugtracker\env\lib\site-packages\sqlalchemy\orm\mapper.py", line 3245, in configure_mappers
    raise e
sqlalchemy.exc.InvalidRequestError: One or more mappers failed to initialize - can't proceed with initialization of other mappers. Triggering mapper: 'mapped class User->users'. Original exception was: Could not determine join condition between parent/child tables on relationship User.tickets - there are multiple foreign key paths linking the tables.  Specify the 'foreign_keys' argument, providing a list of those columns which should be counted as containing a foreign key reference to the parent table.
2020-02-12 08:02:06,102 ERROR: Exception on /login [POST] [in c:\users\josep\onedrive\documents\programming\portfolio\bugtracker\env\lib\site-packages\flask\app.py:1890]
Traceback (most recent call last):
  File "c:\users\josep\onedrive\documents\programming\portfolio\bugtracker\env\lib\site-packages\flask\app.py", line 2446, in wsgi_app
    response = self.full_dispatch_request()
  File "c:\users\josep\onedrive\documents\programming\portfolio\bugtracker\env\lib\site-packages\flask\app.py", line 1951, in full_dispatch_request
    rv = self.handle_user_exception(e)
  File "c:\users\josep\onedrive\documents\programming\portfolio\bugtracker\env\lib\site-packages\flask\app.py", line 1820, in handle_user_exception
    reraise(exc_type, exc_value, tb)
  File "c:\users\josep\onedrive\documents\programming\portfolio\bugtracker\env\lib\site-packages\flask\_compat.py", line 39, in reraise
    raise value
  File "c:\users\josep\onedrive\documents\programming\portfolio\bugtracker\env\lib\site-packages\flask\app.py", line 1949, in full_dispatch_request
    rv = self.dispatch_request()
  File "c:\users\josep\onedrive\documents\programming\portfolio\bugtracker\env\lib\site-packages\flask\app.py", line 1935, in dispatch_request
    return self.view_functions[rule.endpoint](**req.view_args)
  File "C:\Users\josep\OneDrive\Documents\Programming\Portfolio\bugTracker\app\routes.py", line 30, in login
    user = User.query.filter_by(username=form.username.data).first()
  File "c:\users\josep\onedrive\documents\programming\portfolio\bugtracker\env\lib\site-packages\flask_sqlalchemy\__init__.py", line 517, in __get__
    mapper = orm.class_mapper(type)
  File "c:\users\josep\onedrive\documents\programming\portfolio\bugtracker\env\lib\site-packages\sqlalchemy\orm\base.py", line 441, in class_mapper
    mapper = _inspect_mapped_class(class_, configure=configure)
  File "c:\users\josep\onedrive\documents\programming\portfolio\bugtracker\env\lib\site-packages\sqlalchemy\orm\base.py", line 420, in _inspect_mapped_class
    mapper._configure_all()
  File "c:\users\josep\onedrive\documents\programming\portfolio\bugtracker\env\lib\site-packages\sqlalchemy\orm\mapper.py", line 1337, in _configure_all
    configure_mappers()
  File "c:\users\josep\onedrive\documents\programming\portfolio\bugtracker\env\lib\site-packages\sqlalchemy\orm\mapper.py", line 3245, in configure_mappers
    raise e
sqlalchemy.exc.InvalidRequestError: One or more mappers failed to initialize - can't proceed with initialization of other mappers. Triggering mapper: 'mapped class User->users'. Original exception was: Could not determine join condition between parent/child tables on relationship User.tickets - there are multiple foreign key paths linking the tables.  Specify the 'foreign_keys' argument, providing a list of those columns which should be counted as containing a foreign key reference to the parent table.
2020-02-12 08:02:12,179 ERROR: Exception on /login [POST] [in c:\users\josep\onedrive\documents\programming\portfolio\bugtracker\env\lib\site-packages\flask\app.py:1890]
Traceback (most recent call last):
  File "c:\users\josep\onedrive\documents\programming\portfolio\bugtracker\env\lib\site-packages\flask\app.py", line 2446, in wsgi_app
    response = self.full_dispatch_request()
  File "c:\users\josep\onedrive\documents\programming\portfolio\bugtracker\env\lib\site-packages\flask\app.py", line 1951, in full_dispatch_request
    rv = self.handle_user_exception(e)
  File "c:\users\josep\onedrive\documents\programming\portfolio\bugtracker\env\lib\site-packages\flask\app.py", line 1820, in handle_user_exception
    reraise(exc_type, exc_value, tb)
  File "c:\users\josep\onedrive\documents\programming\portfolio\bugtracker\env\lib\site-packages\flask\_compat.py", line 39, in reraise
    raise value
  File "c:\users\josep\onedrive\documents\programming\portfolio\bugtracker\env\lib\site-packages\flask\app.py", line 1949, in full_dispatch_request
    rv = self.dispatch_request()
  File "c:\users\josep\onedrive\documents\programming\portfolio\bugtracker\env\lib\site-packages\flask\app.py", line 1935, in dispatch_request
    return self.view_functions[rule.endpoint](**req.view_args)
  File "C:\Users\josep\OneDrive\Documents\Programming\Portfolio\bugTracker\app\routes.py", line 30, in login
    user = User.query.filter_by(username=form.username.data).first()
  File "c:\users\josep\onedrive\documents\programming\portfolio\bugtracker\env\lib\site-packages\flask_sqlalchemy\__init__.py", line 517, in __get__
    mapper = orm.class_mapper(type)
  File "c:\users\josep\onedrive\documents\programming\portfolio\bugtracker\env\lib\site-packages\sqlalchemy\orm\base.py", line 441, in class_mapper
    mapper = _inspect_mapped_class(class_, configure=configure)
  File "c:\users\josep\onedrive\documents\programming\portfolio\bugtracker\env\lib\site-packages\sqlalchemy\orm\base.py", line 420, in _inspect_mapped_class
    mapper._configure_all()
  File "c:\users\josep\onedrive\documents\programming\portfolio\bugtracker\env\lib\site-packages\sqlalchemy\orm\mapper.py", line 1337, in _configure_all
    configure_mappers()
  File "c:\users\josep\onedrive\documents\programming\portfolio\bugtracker\env\lib\site-packages\sqlalchemy\orm\mapper.py", line 3245, in configure_mappers
    raise e
sqlalchemy.exc.InvalidRequestError: One or more mappers failed to initialize - can't proceed with initialization of other mappers. Triggering mapper: 'mapped class User->users'. Original exception was: Could not determine join condition between parent/child tables on relationship User.tickets - there are multiple foreign key paths linking the tables.  Specify the 'foreign_keys' argument, providing a list of those columns which should be counted as containing a foreign key reference to the parent table.
